Traceback (most recent call last):
  File "/usr/share/miniconda3/envs/pydda-docs/lib/python3.10/site-packages/nbclient/client.py", line 782, in _async_poll_for_reply
    msg = await ensure_async(self.kc.shell_channel.get_msg(timeout=new_timeout))
  File "/usr/share/miniconda3/envs/pydda-docs/lib/python3.10/site-packages/jupyter_core/utils/__init__.py", line 198, in ensure_async
    result = await obj
  File "/usr/share/miniconda3/envs/pydda-docs/lib/python3.10/site-packages/jupyter_client/channels.py", line 313, in get_msg
    raise Empty
_queue.Empty

During handling of the above exception, another exception occurred:

Traceback (most recent call last):
  File "/usr/share/miniconda3/envs/pydda-docs/lib/python3.10/site-packages/jupyter_cache/executors/utils.py", line 58, in single_nb_execution
    executenb(
  File "/usr/share/miniconda3/envs/pydda-docs/lib/python3.10/site-packages/nbclient/client.py", line 1314, in execute
    return NotebookClient(nb=nb, resources=resources, km=km, **kwargs).execute()
  File "/usr/share/miniconda3/envs/pydda-docs/lib/python3.10/site-packages/jupyter_core/utils/__init__.py", line 165, in wrapped
    return loop.run_until_complete(inner)
  File "/usr/share/miniconda3/envs/pydda-docs/lib/python3.10/asyncio/base_events.py", line 649, in run_until_complete
    return future.result()
  File "/usr/share/miniconda3/envs/pydda-docs/lib/python3.10/site-packages/nbclient/client.py", line 709, in async_execute
    await self.async_execute_cell(
  File "/usr/share/miniconda3/envs/pydda-docs/lib/python3.10/site-packages/nbclient/client.py", line 1005, in async_execute_cell
    exec_reply = await self.task_poll_for_reply
  File "/usr/share/miniconda3/envs/pydda-docs/lib/python3.10/site-packages/nbclient/client.py", line 806, in _async_poll_for_reply
    error_on_timeout_execute_reply = await self._async_handle_timeout(timeout, cell)
  File "/usr/share/miniconda3/envs/pydda-docs/lib/python3.10/site-packages/nbclient/client.py", line 856, in _async_handle_timeout
    raise CellTimeoutError.error_from_timeout_and_cell(
nbclient.exceptions.CellTimeoutError: A cell timed out while it was being executed, after 30 seconds.
The message was: Cell execution timed out.
Here is a preview of the cell contents:
-------------------
['## Do imports', 'import pydda', 'import matplotlib.pyplot as plt', 'import warnings', 'from datatree import DataTree']
...
['    w_vel_contours=[1, 2, 5, 10],', '    quiver_spacing_x_km=50.0,', '    quiver_spacing_y_km=50.0,', '    quiverkey_loc="bottom_right",', ')']
-------------------

